ValueError: Input y contains NaN.
Traceback:
File "/home/runner/workspace/.pythonlibs/lib/python3.11/site-packages/streamlit/runtime/scriptrunner/exec_code.py", line 121, in exec_func_with_error_handling
    result = func()
             ^^^^^^
File "/home/runner/workspace/.pythonlibs/lib/python3.11/site-packages/streamlit/runtime/scriptrunner/script_runner.py", line 591, in code_to_exec
    exec(code, module.__dict__)
File "/home/runner/workspace/main.py", line 342, in <module>
    main()
File "/home/runner/workspace/main.py", line 314, in main
    ml_metrics = evaluator.evaluate_ml_utility(
                 ^^^^^^^^^^^^^^^^^^^^^^^^^^^^^^
File "/home/runner/workspace/src/utils/evaluation.py", line 168, in evaluate_ml_utility
    synthetic_model.fit(X_synthetic_processed, y_synthetic)
File "/home/runner/workspace/.pythonlibs/lib/python3.11/site-packages/sklearn/base.py", line 1389, in wrapper
    return fit_method(estimator, *args, **kwargs)
           ^^^^^^^^^^^^^^^^^^^^^^^^^^^^^^^^^^^^^^
File "/home/runner/workspace/.pythonlibs/lib/python3.11/site-packages/sklearn/ensemble/_forest.py", line 360, in fit
    X, y = validate_data(
           ^^^^^^^^^^^^^^
File "/home/runner/workspace/.pythonlibs/lib/python3.11/site-packages/sklearn/utils/validation.py", line 2961, in validate_data
    X, y = check_X_y(X, y, **check_params)
           ^^^^^^^^^^^^^^^^^^^^^^^^^^^^^^^
File "/home/runner/workspace/.pythonlibs/lib/python3.11/site-packages/sklearn/utils/validation.py", line 1387, in check_X_y
    y = _check_y(y, multi_output=multi_output, y_numeric=y_numeric, estimator=estimator)
        ^^^^^^^^^^^^^^^^^^^^^^^^^^^^^^^^^^^^^^^^^^^^^^^^^^^^^^^^^^^^^^^^^^^^^^^^^^^^^^^^
File "/home/runner/workspace/.pythonlibs/lib/python3.11/site-packages/sklearn/utils/validation.py", line 1397, in _check_y
    y = check_array(
        ^^^^^^^^^^^^
File "/home/runner/workspace/.pythonlibs/lib/python3.11/site-packages/sklearn/utils/validation.py", line 1107, in check_array
    _assert_all_finite(
File "/home/runner/workspace/.pythonlibs/lib/python3.11/site-packages/sklearn/utils/validation.py", line 120, in _assert_all_finite
    _assert_all_finite_element_wise(
File "/home/runner/workspace/.pythonlibs/lib/python3.11/site-packages/sklearn/utils/validation.py", line 169, in _assert_all_finite_element_wise
    raise ValueError(msg_err)